<?xml version="1.0" ?>
<!-- =================================================================================== -->
<!-- |    This document was autogenerated by xacro from car.urdf.xacro                 | -->
<!-- |    EDITING THIS FILE BY HAND IS NOT RECOMMENDED                                 | -->
<!-- =================================================================================== -->
<robot name="car">
  <material name="pla">
    <color rgba="0.5 0.1 0.5 1.0"/>
  </material>
  <material name="pla_black">
    <color rgba="0.3 0.3 0.3 1.0"/>
  </material>
  <material name="aluminum">
    <color rgba="0.75 0.75 0.75 1.0"/>
  </material>
  <material name="rubber">
    <color rgba="0.1 0.1 0.1 1"/>
  </material>
  <link name="base_link">
    <inertial>
      <origin rpy="0 -0 0" xyz="0 -0 0.01"/>
      <mass value="1.2"/>
      <inertia ixx="0.00164" ixy="0" ixz="0" iyy="0.01" iyz="0" izz="0.00964"/>
    </inertial>
    <visual>
      <origin rpy="0 -0 0" xyz="-0 0 0.095"/>
      <geometry>
        <box size="0.3 0.08 0.1"/>
      </geometry>
      <material name="pla"/>
    </visual>
    <collision>
      <origin rpy="0 -0 0" xyz="-0 0 0.1"/>
      <geometry>
        <box size="0.34 0.1 0.1"/>
      </geometry>
    </collision>
  </link>
  <link name="base_footprint"/>
  <joint name="base_joint" type="fixed">
    <parent link="base_link"/>
    <child link="base_footprint"/>
    <origin rpy="0.0 0.0 0.0" xyz="0.0 0.0 -0.0"/>
  </joint>
  <link name="base_laser">
    <inertial>
      <mass value="0.0"/>
      <inertia ixx="0.0" ixy="0.0" ixz="0.0" iyy="0.0" iyz="0.0" izz="0.0"/>
    </inertial>
    <collision>
      <geometry>
        <cylinder length="0.04" radius="0.05"/>
      </geometry>
    </collision>
    <visual>
      <geometry>
        <cylinder length="0.04" radius="0.05"/>
      </geometry>
      <material name="pla_black"/>
    </visual>
  </link>
  <link name="camera_link">
    <inertial>
      <mass value="0.0"/>
      <inertia ixx="0.0" ixy="0.0" ixz="0.0" iyy="0.0" iyz="0.0" izz="0.0"/>
    </inertial>
    <collision>
      <geometry>
        <box size="0.025 0.09 0.025"/>
      </geometry>
    </collision>
    <visual>
      <geometry>
        001
            
        <box size="0.025 0.09 0.025"/>
      </geometry>
      <material name="aluminum"/>
    </visual>
  </link>
  <link name="rear_left_wheel">
    <inertial>
      <mass value="0.1"/>
      <inertia ixx="0.0000729" ixy="0" ixz="0" iyy="0.0000729" iyz="0" izz="0.0001458"/>
    </inertial>
    <visual>
      <geometry>
        <cylinder length="0.043" radius="0.054"/>
      </geometry>
      <material name="rubber"/>
    </visual>
    <collision name="collision">
      <geometry>
        <cylinder length="0.043" radius="0.054"/>
      </geometry>
    </collision>
  </link>
  <link name="rear_right_wheel">
    <inertial>
      <mass value="0.1"/>
      <inertia ixx="0.0000729" ixy="0" ixz="0" iyy="0.0000729" iyz="0" izz="0.0001458"/>
    </inertial>
    <visual>
      <geometry>
        <cylinder length="0.043" radius="0.054"/>
      </geometry>
      <material name="rubber"/>
    </visual>
    <collision name="collision">
      <geometry>
        <cylinder length="0.043" radius="0.054"/>
      </geometry>
    </collision>
  </link>
  <link name="front_left_wheel">
    <inertial>
      <mass value="0.1"/>
      <inertia ixx="0.0000729" ixy="0" ixz="0" iyy="0.0000729" iyz="0" izz="0.0001458"/>
    </inertial>
    <visual>
      <geometry>
        <cylinder length="0.043" radius="0.054"/>
      </geometry>
      <material name="rubber"/>
    </visual>
    <collision name="collision">
      <geometry>
        <cylinder length="0.043" radius="0.054"/>
      </geometry>
    </collision>
  </link>
  <link name="front_right_wheel">
    <inertial>
      <mass value="0.1"/>
      <inertia ixx="0.0000729" ixy="0" ixz="0" iyy="0.0000729" iyz="0" izz="0.0001458"/>
    </inertial>
    <visual>
      <geometry>
        <cylinder length="0.043" radius="0.054"/>
      </geometry>
      <material name="rubber"/>
    </visual>
    <collision name="collision">
      <geometry>
        <cylinder length="0.043" radius="0.054"/>
      </geometry>
    </collision>
  </link>
  <link name="front_left_hub">
    <inertial>
      <mass value="0.0"/>
      <inertia ixx="0.0" ixy="0" ixz="0" iyy="0.0" iyz="0" izz="0.0"/>
    </inertial>
    <collision name="collision">
      <geometry>
        <box size="0.05 0.08 0.05"/>
      </geometry>
    </collision>
  </link>
  <link name="front_right_hub">
    <inertial>
      <mass value="0.0"/>
      <inertia ixx="0.0" ixy="0" ixz="0" iyy="0.0" iyz="0" izz="0.0"/>
    </inertial>
    <collision name="collision">
      <geometry>
        <box size="0.05 0.08 0.05"/>
      </geometry>
    </collision>
  </link>
  <joint name="lidar_sensor_joint" type="fixed">
    <origin rpy="0 0 0" xyz="0.08 -0 0.18"/>
    <parent link="base_link"/>
    <child link="base_laser"/>
  </joint>
  <joint name="camera_sensor_joint" type="fixed">
    <origin rpy="0 0 0" xyz="0.14 -0 0.13"/>
    <parent link="base_link"/>
    <child link="camera_link"/>
  </joint>
  <joint name="rear_left_wheel_joint" type="continuous">
    <origin rpy="-1.5707 0 0" xyz="-0.14 0.13 0.054"/>
    <parent link="base_link"/>
    <child link="rear_left_wheel"/>
    <axis xyz="0 0 1"/>
  </joint>
  <joint name="rear_right_wheel_joint" type="continuous">
    <origin rpy="-1.5707 0 0" xyz="-0.14 -0.13 0.054"/>
    <parent link="base_link"/>
    <child link="rear_right_wheel"/>
    <axis xyz="0 0 1"/>
  </joint>
  <joint name="front_left_wheel_joint" type="continuous">
    <origin rpy="-1.5707 0 0" xyz="-0 0.02 0"/>
    <parent link="front_left_hub"/>
    <child link="front_left_wheel"/>
    <axis xyz="0 0 1"/>
  </joint>
  <joint name="front_right_wheel_joint" type="continuous">
    <origin rpy="-1.5707 0 0" xyz="-0 -0.02 0"/>
    <parent link="front_right_hub"/>
    <child link="front_right_wheel"/>
    <axis xyz="0 0 1"/>
  </joint>
  <joint name="front_left_hub_joint" type="revolute">
    <origin rpy="0 0 0" xyz="0.14 0.11 0.054"/>
    <limit effort="1000" lower="-0.5" upper="0.5" velocity="100.0"/>
    <parent link="base_link"/>
    <child link="front_left_hub"/>
    <axis xyz="0 0 1"/>
  </joint>
  <joint name="front_right_hub_joint" type="revolute">
    <origin rpy="0 0 0" xyz="0.14 -0.11 0.054"/>
    <limit effort="1000" lower="-0.5" upper="0.5" velocity="100.0"/>
    <parent link="base_link"/>
    <child link="front_right_hub"/>
    <axis xyz="0 0 1"/>
  </joint>
</robot>
